<?xml version="1.0" ?>
<robot name="Sim" xmlns:xacro="http://www.ros.org/wiki/xacro">

<xacro:include filename="$(find rover_sim)/urdf/materials.xacro" />
<xacro:include filename="$(find rover_sim)/urdf/Sim.trans" />
<xacro:include filename="$(find rover_sim)/urdf/Sim.gazebo" />
<link name="base_link">
  <inertial>
    <origin rpy="0 0 0" xyz="0.0006007577009604456 -2.0009250954814774e-19 0.1912775586930594"/>
    <mass value="105.11118623932714"/>
    <inertia ixx="3.347522" ixy="0.0" ixz="-0.005562" iyy="10.805776" iyz="0.0" izz="13.757255"/>
  </inertial>
  <visual>
    <origin rpy="0 0 0" xyz="0 0 0"/>
    <geometry>
      <mesh filename="package://rover_sim/meshes/base_link.stl" scale="0.001 0.001 0.001"/>
    </geometry>
    <material name="silver"/>
  </visual>
  <collision>
    <origin rpy="0 0 0" xyz="0 0 0"/>
    <geometry>
      <mesh filename="package://rover_sim/meshes/base_link.stl" scale="0.001 0.001 0.001"/>
    </geometry>
  </collision>
</link>

<link name="wheel1_1">
  <inertial>
    <origin rpy="0 0 0" xyz="-1.1102230246251565e-16 -0.03810000000000002 3.6914915568786455e-15"/>
    <mass value="5.17079983877615"/>
    <inertia ixx="0.032526" ixy="0.0" ixz="0.0" iyy="0.060048" iyz="0.0" izz="0.032526"/>
  </inertial>
  <visual>
    <origin rpy="0 0 0" xyz="-0.275 0.31 -0.1524"/>
    <geometry>
      <mesh filename="package://rover_sim/meshes/wheel1_1.stl" scale="0.001 0.001 0.001"/>
    </geometry>
    <material name="silver"/>
  </visual>
  <collision>
    <origin rpy="0 0 0" xyz="-0.275 0.31 -0.1524"/>
    <geometry>
      <mesh filename="package://rover_sim/meshes/wheel1_1.stl" scale="0.001 0.001 0.001"/>
    </geometry>
  </collision>
</link>

<link name="wheel4_1">
  <inertial>
    <origin rpy="0 0 0" xyz="-5.551115123125783e-17 -0.038099999999999856 3.6914915568786455e-15"/>
    <mass value="5.17079983877615"/>
    <inertia ixx="0.032526" ixy="-0.0" ixz="0.0" iyy="0.060048" iyz="0.0" izz="0.032526"/>
  </inertial>
  <visual>
    <origin rpy="0 0 0" xyz="0.275 0.31 -0.1524"/>
    <geometry>
      <mesh filename="package://rover_sim/meshes/wheel4_1.stl" scale="0.001 0.001 0.001"/>
    </geometry>
    <material name="silver"/>
  </visual>
  <collision>
    <origin rpy="0 0 0" xyz="0.275 0.31 -0.1524"/>
    <geometry>
      <mesh filename="package://rover_sim/meshes/wheel4_1.stl" scale="0.001 0.001 0.001"/>
    </geometry>
  </collision>
</link>

<link name="wheel3_1">
  <inertial>
    <origin rpy="0 0 0" xyz="1.1102230246251565e-16 0.03810000000000002 3.6914915568786455e-15"/>
    <mass value="5.17079983877615"/>
    <inertia ixx="0.032526" ixy="-0.0" ixz="0.0" iyy="0.060048" iyz="-0.0" izz="0.032526"/>
  </inertial>
  <visual>
    <origin rpy="0 0 0" xyz="0.275 -0.31 -0.1524"/>
    <geometry>
      <mesh filename="package://rover_sim/meshes/wheel3_1.stl" scale="0.001 0.001 0.001"/>
    </geometry>
    <material name="silver"/>
  </visual>
  <collision>
    <origin rpy="0 0 0" xyz="0.275 -0.31 -0.1524"/>
    <geometry>
      <mesh filename="package://rover_sim/meshes/wheel3_1.stl" scale="0.001 0.001 0.001"/>
    </geometry>
  </collision>
</link>

<link name="wheel2_1">
  <inertial>
    <origin rpy="0 0 0" xyz="1.1102230246251565e-16 0.038099999999999856 3.6914915568786455e-15"/>
    <mass value="5.17079983877615"/>
    <inertia ixx="0.032526" ixy="0.0" ixz="0.0" iyy="0.060048" iyz="0.0" izz="0.032526"/>
  </inertial>
  <visual>
    <origin rpy="0 0 0" xyz="-0.275 -0.31 -0.1524"/>
    <geometry>
      <mesh filename="package://rover_sim/meshes/wheel2_1.stl" scale="0.001 0.001 0.001"/>
    </geometry>
    <material name="silver"/>
  </visual>
  <collision>
    <origin rpy="0 0 0" xyz="-0.275 -0.31 -0.1524"/>
    <geometry>
      <mesh filename="package://rover_sim/meshes/wheel2_1.stl" scale="0.001 0.001 0.001"/>
    </geometry>
  </collision>
</link>

<link name="lidar_1">
  <inertial>
    <origin rpy="0 0 0" xyz="5.551115123125783e-17 -1.388112759759698e-16 0.01250000000000362"/>
    <mass value="0.10789485809488791"/>
    <inertia ixx="4.1e-05" ixy="-0.0" ixz="0.0" iyy="4.1e-05" iyz="-0.0" izz="7e-05"/>
  </inertial>
  <visual>
    <origin rpy="0 0 0" xyz="-0.4 0.0 -0.29615"/>
    <geometry>
      <mesh filename="package://rover_sim/meshes/lidar_1.stl" scale="0.001 0.001 0.001"/>
    </geometry>
    <material name="silver"/>
  </visual>
  <collision>
    <origin rpy="0 0 0" xyz="-0.4 0.0 -0.29615"/>
    <geometry>
      <mesh filename="package://rover_sim/meshes/lidar_1.stl" scale="0.001 0.001 0.001"/>
    </geometry>
  </collision>
</link>

<joint name="Rev6" type="continuous">
  <origin rpy="0 0 0" xyz="0.275 -0.31 0.1524"/>
  <parent link="base_link"/>
  <child link="wheel1_1"/>
  <axis xyz="-0.0 1.0 0.0"/>
  <!--  xyz="-0.0 -1.0 0.0" -->
</joint>

<joint name="Rev7" type="continuous">
  <origin rpy="0 0 0" xyz="-0.275 -0.31 0.1524"/>
  <parent link="base_link"/>
  <child link="wheel4_1"/>
  <axis xyz="-0.0 1.0 0.0"/>
  <!--  xyz="-0.0 -1.0 0.0" -->
</joint>

<joint name="Rev8" type="continuous">
  <origin rpy="0 0 0" xyz="-0.275 0.31 0.1524"/>
  <parent link="base_link"/>
  <child link="wheel3_1"/>
  <axis xyz="0.0 1.0 0.0"/>
</joint>

<joint name="Rev9" type="continuous">
  <origin rpy="0 0 0" xyz="0.275 0.31 0.1524"/>
  <parent link="base_link"/>
  <child link="wheel2_1"/>
  <axis xyz="0.0 1.0 0.0"/>
</joint>

<joint name="Rigid10" type="fixed">
  <origin rpy="0 0 0" xyz="0.4 0.0 0.29615"/>
  <parent link="base_link"/>
  <child link="lidar_1"/>
</joint>

</robot>
