<?xml version="1.0"?>

<sdf version='1.7'>
  <model name='rover'>
    <link name='wheel_1'>
      <inertial>
        <pose>0 0 0 0 -0 0</pose>
        <mass>0.00629423</mass>
        <inertia>
          <ixx>3.792</ixx>
          <ixy>0</ixy>
          <ixz>0</ixz>
          <iyy>3.792</iyy>
          <iyz>0</iyz>
          <izz>7.071</izz>
        </inertia>
      </inertial>
      <collision name='wheel_1_collision'>
        <pose>-0.302073 -0.274046 0.0375 -1.5708 -1.5708 0</pose>
        <geometry>
          <mesh>
            <scale>0.001 0.001 0.001</scale>
            <uri>model://my_simulations/urdf/wheel_1.stl</uri>
          </mesh>
        </geometry>
      </collision>
      <visual name='wheel_1_visual'>
        <pose>-0.302073 -0.274046 0.0375 -1.5708 -1.5708 0</pose>
        <geometry>
          <mesh>
            <scale>0.001 0.001 0.001</scale>
            <uri>model://my_simulations/urdf/wheel_1.stl</uri>
          </mesh>
        </geometry>
      </visual>
    </link>
    <joint name='wheel4' type='revolute'>
      <pose relative_to='wheel_1'>-0.327073 -0.274046 0.0375 -1.5708 0 1.5708</pose>
      <parent>wheel_1</parent>
      <child>base</child>
      <axis>
        <xyz>0 0 1</xyz>
        <limit>
          <effort>1</effort>
          <velocity>20</velocity>
          <lower>-1e+16</lower>
          <upper>1e+16</upper>
        </limit>
        <dynamics>
          <spring_reference>0</spring_reference>
          <spring_stiffness>0</spring_stiffness>
        </dynamics>
      </axis>
    </joint>
    <link name='base'>
      <pose relative_to='wheel4'>0 0 0 0 -0 0</pose>
      <inertial>
        <pose>-0.078689 -0.050312 -0.146272 0 -0 0</pose>
        <mass>0.279507</mass>
        <inertia>
          <ixx>0.0142664</ixx>
          <ixy>-0.00136778</ixy>
          <ixz>-0.00397658</ixz>
          <iyy>0.0205311</iyy>
          <iyz>-0.00254251</iyz>
          <izz>0.0140138</izz>
        </inertia>
      </inertial>
      <collision name='base_collision'>
        <pose>0.274046 0.0375 -0.327073 1.5708 1.5708 0</pose>
        <geometry>
          <mesh>
            <scale>0.001 0.001 0.001</scale>
            <uri>model://my_simulations/urdf/base.stl</uri>
          </mesh>
        </geometry>
      </collision>
      <collision name='base_fixed_joint_lump__lidar_base_collision_1'>
        <pose>-0.190677 -0.1225 -0.324236 1.57079 -0 0</pose>
        <geometry>
          <mesh>
            <scale>0.001 0.001 0.001</scale>
            <uri>model://my_simulations/urdf/lidar_base.stl</uri>
          </mesh>
        </geometry>
      </collision>
      <visual name='base_visual'>
        <pose>0.274046 0.0375 -0.327073 1.5708 1.5708 0</pose>
        <geometry>
          <mesh>
            <scale>0.001 0.001 0.001</scale>
            <uri>model://my_simulations/urdf/base.stl</uri>
          </mesh>
        </geometry>
      </visual>
      <visual name='base_fixed_joint_lump__lidar_base_visual_1'>
        <pose>-0.190677 -0.1225 -0.324236 1.57079 -0 0</pose>
        <geometry>
          <mesh>
            <scale>0.001 0.001 0.001</scale>
            <uri>model://my_simulations/urdf/lidar_base.stl</uri>
          </mesh>
        </geometry>
      </visual>
    </link>
    <joint name='wheel1' type='revolute'>
      <pose relative_to='base'>0 0 -0.63 3.14159 -0 0</pose>
      <parent>base</parent>
      <child>wheel_1_2</child>
      <axis>
        <xyz>0 0 1</xyz>
        <limit>
          <effort>1</effort>
          <velocity>20</velocity>
          <lower>-1e+16</lower>
          <upper>1e+16</upper>
        </limit>
        <dynamics>
          <spring_reference>0</spring_reference>
          <spring_stiffness>0</spring_stiffness>
        </dynamics>
      </axis>
    </joint>
    <link name='wheel_1_2'>
      <pose relative_to='wheel1'>0 0 0 0 -0 0</pose>
      <inertial>
        <pose>0 0 0 0 -0 0</pose>
        <mass>0.00629423</mass>
        <inertia>
          <ixx>3.792</ixx>
          <ixy>0</ixy>
          <ixz>0</ixz>
          <iyy>3.792</iyy>
          <iyz>0</iyz>
          <izz>7.071</izz>
        </inertia>
      </inertial>
      <collision name='wheel_1_2_collision'>
        <pose>0 0 0.076 1.5708 -0 0</pose>
        <geometry>
          <mesh>
            <scale>0.001 0.001 0.001</scale>
            <uri>model://my_simulations/urdf/wheel_1.stl</uri>
          </mesh>
        </geometry>
      </collision>
      <visual name='wheel_1_2_visual'>
        <pose>0 0 0.076 1.5708 -0 0</pose>
        <geometry>
          <mesh>
            <scale>0.001 0.001 0.001</scale>
            <uri>model://my_simulations/urdf/wheel_1.stl</uri>
          </mesh>
        </geometry>
      </visual>
    </link>
    <joint name='wheel2' type='revolute'>
      <pose relative_to='base'>0.548092 -0 -0.63 0 -0 3.14159</pose>
      <parent>base</parent>
      <child>wheel_1_3</child>
      <axis>
        <xyz>0 0 1</xyz>
        <limit>
          <effort>1</effort>
          <velocity>20</velocity>
          <lower>-1e+16</lower>
          <upper>1e+16</upper>
        </limit>
        <dynamics>
          <spring_reference>0</spring_reference>
          <spring_stiffness>0</spring_stiffness>
        </dynamics>
      </axis>
    </joint>
    <link name='wheel_1_3'>
      <pose relative_to='wheel2'>0 0 0 0 -0 0</pose>
      <inertial>
        <pose>0 0 0 0 -0 0</pose>
        <mass>0.00629423</mass>
        <inertia>
          <ixx>3.792</ixx>
          <ixy>0</ixy>
          <ixz>0</ixz>
          <iyy>3.792</iyy>
          <iyz>0</iyz>
          <izz>7.071</izz>
        </inertia>
      </inertial>
      <collision name='wheel_1_3_collision'>
        <pose>0 0 0 1.5708 -0 0</pose>
        <geometry>
          <mesh>
            <scale>0.001 0.001 0.001</scale>
            <uri>model://my_simulations/urdf/wheel_1.stl</uri>
          </mesh>
        </geometry>
      </collision>
      <visual name='wheel_1_3_visual'>
        <pose>0 0 0 1.5708 -0 0</pose>
        <geometry>
          <mesh>
            <scale>0.001 0.001 0.001</scale>
            <uri>model://my_simulations/urdf/wheel_1.stl</uri>
          </mesh>
        </geometry>
      </visual>
    </link>
    <joint name='wheel3' type='revolute'>
      <pose relative_to='base'>0.548092 0 -0.025 3.14159 -0 -1.5708</pose>
      <parent>base</parent>
      <child>wheel_1_4</child>
      <axis>
        <xyz>0 0 1</xyz>
        <limit>
          <effort>1</effort>
          <velocity>20</velocity>
          <lower>-1e+16</lower>
          <upper>1e+16</upper>
        </limit>
        <dynamics>
          <spring_reference>0</spring_reference>
          <spring_stiffness>0</spring_stiffness>
        </dynamics>
      </axis>
    </joint>
    <link name='wheel_1_4'>
      <pose relative_to='wheel3'>0 0 0 0 -0 0</pose>
      <inertial>
        <pose>0 0 0 0 -0 0</pose>
        <mass>0.00629423</mass>
        <inertia>
          <ixx>3.792</ixx>
          <ixy>0</ixy>
          <ixz>0</ixz>
          <iyy>3.792</iyy>
          <iyz>0</iyz>
          <izz>7.071</izz>
        </inertia>
      </inertial>
      <collision name='wheel_1_4_collision'>
        <pose>0 0 0 1.5708 -0 0</pose>
        <geometry>
          <mesh>
            <scale>0.001 0.001 0.001</scale>
            <uri>model://my_simulations/urdf/wheel_1.stl</uri>
          </mesh>
        </geometry>
      </collision>
      <visual name='wheel_1_4_visual'>
        <pose>0 0 0 1.5708 -0 0</pose>
        <geometry>
          <mesh>
            <scale>0.001 0.001 0.001</scale>
            <uri>model://my_simulations/urdf/wheel_1.stl</uri>
          </mesh>
        </geometry>
      </visual>
    </link>
  </model>
</sdf>

